Workbook

Sheet C1
A1: Informe pràctica C1 | E1: Data: | F1: 45792
A2: Grup pràctiques: | B2: GRUP 2.1 (G3) tarda - 2on torn | E2: Parella: | F2: T_18
A3: Alumnes: | B3: Sergio Castañeiras Morales i Domènec Huerta Estradé
A5: 1. Descripció de la mostra
B9: Contingut nominal de Fe a la mostra (indicat a l'etiqueta, considereu aquest valor com el valor real): | H9: 5 | I9: g/comprimit
A11: 2. Massa del comprimit (mg): | E11: 12393 | F11: mg
A13: 3. Massa pesada de sal de Mohr (g): | E13: 144 | F13: mg
A15: 4. Càlcul de la concentració de la dissolució estoc de Fe(II):
H17: Dades
H18: PM (sal de Mohr) (g/mol) | I18: 392.14
H19: PM (sal de Mohr) (g/mol) | I19: 55.845
H21: Resultat amb excel
H22: Quantitat de Fe^(2+) (mg) | J22: =E13*I19/I18 -> 20.507166
H23: Concentració Fe^(2+) (mg Fe^(2+)/mL) | J23: =J22/500 -> 0.041014332
O24: 0.041
A30: 5. Concentració dissolució treball Fe(II) (mg/mL): | F30: =J23*25/50 -> 0.020507166 | G30: mg/mL
A33: 6. Concentració de Fe(II) a la dissolució del comprimit (g/mL): | F33: =5*10^(-3)/100 -> 5e-05 | G33: g/mL | H33: Aquest valor s'obté a partir de les dades del contingut vitamínic que apareix a l'envàs
A36: 7. Gotes (o volum) emprat al punt (1) de la pràctica: | F36: Per 10 mL de la dissolució de treball de 0.02 ppm de Fe(II) amb 3 gotes d'acetat de sodi 2M hem arribat a un pH d'aproximadament 4
A38: 8. Ompliu la taula fent servir fórmules a les caselles a on s'hagin de fer càlculs i no afegint només el resultat (clica sobre el 6 per veure exemple i esborra'l)
C40: Volum (mL) dissolució de treball de Fe(II) | D40: Gotes (o volum) afegit al matràs | E40: Concentració patró de Fe(II) (mg/mL) | F40: Absorbància
C41: 1 | D41: 1 | E41: =C41*$F$30/25 -> 0.00082028663 | F41: 0.156
C42: 2 | D42: 1 | E42: =$F$30*C42/25 -> 0.0016405733 | F42: 0.331
C43: 3 | D43: 1 | E43: =$F$30*C43/25 -> 0.0024608599 | F43: 0.496
C44: 4 | D44: 1 | E44: =$F$30*C44/25 -> 0.0032811465 | F44: 0.675
C45: 5 | D45: 1 | E45: =$F$30*C45/25 -> 0.0041014332 | F45: 0.868
A47: 9. Exemple del càlcul de la concentració d'un patro de Fe(II):
A61: 10. Volum teòric de dissolució que s'ha de pipetejar per tenir una
A62: absorbància a la part central de la recta: | E62: =25*E43/(F33*10^3) -> 1.2304299 | F62: mL
A64: 11. Volum real pipetejat: | E64: 1 | F64: mL
A66: 12. Absorbància del blanc de la mostra: | E66: 0.023
A68: 13. Absorbància mesurada de la mostra: | E68: 0.456
A70: 14. Absorbància corregida de la mostra: | E70: =E68-E66 -> 0.433
A72: 15. Representeu la recta de calibratge:
H73: Absorbància = m * [Fe (II)] + n
H74: m | I74: {=LINEST(F41:F45,E41:E45,1,1)} -> 215.53442 | J74: -0.0252 | K74: n
H75: u_m | I75: 3.4795601 | J75: 0.0094664319 | K75: u_n
H76: R^2 | I76: 0.99921874 | J76: 0.0090258887 | K76: S_{y/x}
H77: F | I77: 3836.9362 | J77: 3 | K77: dof
H78: Ssreg | I78: 0.3125824 | J78: 0.0002444 | K78: Ssresid
A88: 16. Concentració de Fe(II) interpolat a la recta de calibratge: | G88: =(E70-J74)/I74 -> 0.0021258786 | H88: mg/mL | J88: Absorbància_{avg} | K88: =AVERAGE(F41:F45) -> 0.5052
...

Sheet C2
A1: Informe pràctica C1 | E1: Data: | F1: 45796
A2: Grup pràctiques: | B2: GRUP 2.1 (G3) tarda - 2on torn | E2: Parella: | F2: T_18
A3: Alumnes: | B3: Sergio Castañeiras Morales i Domènec Huerta Estradé
A5: 1. Descripció de l'instrument AASF utilizat
A8: 2. Massa pesada de sal de Mn (g): | C8: 0.1665
A10: 3. Càlcul de la concentració de la dissolució estoc de Mn(II) i dilucions intermèdies:
E11: Càlcul amb excel
E12: Concentració de manganès en la primera dissolució | G12: =(C8*54.938*10^6)/(169.02*500) -> 108.23781 | H12: ppm
E13: Concentració de manganès en la dissolució diluida | G13: =G12*50/500 -> 10.823781 | H13: ppm
A24: 4. Concentració de Mn(II) a la dissolució del comprimit (g/mL): | D24: =2*10^(-3)/100 -> 2e-05 | E24: g/mL | F24: Aquest és el resultat que obtindriem assumint el valor teòric de l'etiqueta
A27: 5. Dades obtingudes del calibratge per patró extern | D27: Concentració dissolució de treball Ferro | E27: ='C1'!F30*10^3 -> 20.507166 | F27: ppm
A29: Volum de la solució de treball afegit (mL) | B29: Concentració (ppm Fe) | C29: senyal AASF | D29: % RSD | F29: Volum de la solució de treball afegit (mL) | G29: Concentració (ppm Mn) | H29: senyal AASF | I29: % RSD
A30: 1 | B30: =$E$27*A30/25 -> 0.82028663 | C30: 0.0674 | D30: 0.5 | F30: 2 | G30: =2*$G$13/25 -> 0.86590245 | H30: 0.16324 | I30: 1.1
A31: 2 | B31: =$E$27*A31/25 -> 1.6405733 | C31: 0.1212 | D31: 1.5 | F31: 4 | G31: =4*$G$13/25 -> 1.7318049 | H31: 0.3206 | I31: 0.7
A32: 3 | B32: =$E$27*A32/25 -> 2.4608599 | C32: 0.1701 | D32: 1.2 | F32: 6 | G32: =6*$G$13/25 -> 2.5977073 | H32: 0.466 | I32: 0.7
A33: 4 | B33: =$E$27*A33/25 -> 3.2811465 | C33: 0.2093 | D33: 0.8 | F33: 8 | G33: =8*$G$13/25 -> 3.4636098 | H33: 0.6058 | I33: 1.9
A34: 5 | B34: =$E$27*A34/25 -> 4.1014332 | C34: 0.257 | D34: 1 | F34: 10 | G34: =10*$G$13/25 -> 4.3295122 | H34: 0.7387 | I34: 0.4
A36: 3. Representeu les rectes de calibratge pel Fe i pel Mn
F37: Senyal AASF = Concentració Fe(II) * m +n | S37: Senyal AASF = Concentració Mn(II) * m +n
E38: m | F38: {=LINEST(C30:C34,B30:B34,TRUE,TRUE)} -> 0.056967892 | G38: 0.02481 | H38: a | R38: m | S38: {=LINEST(H30:H34,G30:G34,TRUE,TRUE)} -> 0.1658524 | T38: 0.028032 | U38: a
E39: u_m | F39: 0.0017207548 | G39: 0.0046814563 | H39: u_a | R39: u_m | S39: 0.0030967819 | T39: 0.0088935659 | U39: u_a
E40: R^2 | F40: 0.99727032 | G40: 0.0044635935 | H40: S_{y/x} | R40: R^2 | S40: 0.99895517 | T40: 0.0084796824 | U40: S_{y/x}
E41: F | F41: 1096.0296 | G41: 3 | H41: dof | R41: F | S41: 2868.2849 | T41: 3 | U41: dof
E42: Ssreg | F42: 0.021836929 | G42: 5.9771e-05 | H42: Ssresid | R42: Ssreg | S42: 0.20624407 | T42: 0.00021571504 | U42: Ssresid
E44: n | F44: =COUNT(B30:B34) -> 5 | R44: n | S44: =COUNT(G30:G34) -> 5
E45: Senyal AASF_{avg} | F45: =AVERAGE(C30:C34) -> 0.165 | R45: Senyal AASF_{avg} | S45: =AVERAGE(H30:H34) -> 0.458868
E46: s_{xx} | F46: =VARPA(B30:B34)*F44 -> 6.7287016 | R46: s_{xx} | S46: =VARPA(G30:G34)*S44 -> 7.4978705
E47: t_{tab} | F47: =_xlfn.T.INV.2T(0.05,G41) -> 3.1824463 | R47: t_{tab} | S47: =_xlfn.T.INV.2T(0.05,T41) -> 3.1824463
A52: 4. Concentració de Fe en la mostra: | B52: Senyal ASSF de la mostra (Ferro) | C52: % RSD | D52: Concentració de Fe (II) de la mostra (ppm) | F52: Senyal ASSF de la mostra (Manganès) | G52: % RSD | H52: Concentració de Mn (II) de la mostra (ppm)
A53: Concentració de Mn en la mostra: | B53: 0.1538 | C53: 0.4 | D53: =(B53-G38)/F38 -> 2.2642579 | F53: 0.1938 | G53: 1 | H53: =(F53-T38)/S38 -> 0.99949111
A55: 5. Desviació estàndard de la concentració calculada (Fe): | C55: S_0 | D55: Intérval de confiança | F55: S_0 | G55: Intérval de confiança
A56: Desviació estàndard de la concentració calculada (Mn) | C56: =G39/F38*SQRT(1+1/F44+(B53-F45)^2/(F38^2*F46)) -> 0.090235713 | D56: =C56*F47 -> 0.28717031 | F56: =T39/S38*SQRT(1+1/S44+(F53-S45)^2/(S38^2*S46)) -> 0.066559323 | G56: =F56*S47 -> 0.21182147
A58: 6. Contingut de Fe al comprimit (mg) amb el seu interval de confiança: | C58: =D53*100/4.8*0.1 -> 4.717204 | D58: ± | E58: =D56*100/4.8*0.1 -> 0.59827148
A59: Contingut de Mn al comprimit (mg) amb el seu interval de confiança: | C59: =H53*50/2.5*0.1 -> 1.9989822 | D59: ± | E59: =G56*50/2.5*0.1 -> 0.42364294
A61: 7. Comenta els resultats del contingut de ferro trobat pels diferents mètodes amb el contingut indicat a l'etiqueta del producte.
A67: 8. Completa la taula següent (afegiu el vostre resultat i el de la resta de les parelles que han fet la mateixa pràctica):
B68: (es considera que els diferents resultats son replicats de mostra)
A70: Número de parella | B70: Contingut de Fe al comprimit (mg): | C70: Interval de confiança | D70: Concentració mitjana (mg/mL) | E70: Desviació estàndard | F70: Desviació estàndard relativa (%)
A71: T_18 (el nostre) | B71: =C58 -> 4.717204 | C71: =E58 -> 0.59827148 | D71: =AVERAGE(B71:B78) -> 4.8514408 | E71: =STDEV(B71:B78) -> 0.2018814 | F71: =E71/D71*100 -> 4.1612669
A72: M19 | B72: 4.89 | C72: 0.42
...

Sheet Càlculs
