Workbook

Sheet Pràctica A
A1: Informe pràctica F | E1: Data: | F1: 45784
A2: Grup pràctiques: | B2: 2.1. | E2: Parella: | F2: T18
A3: Alumnes: | B3: Sergio Castañeiras i Domènec Huerta Estradé
A5: 1. Descripció de les mostres
A6: Les mostresanalitzades són dissolucions de Co(II) i Ni(II) de 1000ppm. La de cobalt és de color rosa i la de níquel blava, tot i així, en les concentracions analitzades completament transparents
A7: A efectes pràctic, s'ha analitzat dissolucions en el rang de concentracions 0,2-0,5 ppm a través de complexs amb PAR(4-(2-piridilazo)resorcinol, que emet a la regió visible de l'espectre electromagentic
A9: 2. Instrumentació
A10: Per a l'anàlisis de les mostres s'ha utilitzat un espectrofòtometre Jasco V-730 de doble feix, les mostres s'han col·locat en cubetesde quars i les dades obtingudes han estat procesades amb els programes Spectra Manager i Spectra Analysis. Des d'aquests s'han guardaten format .txt per acabar obtenint els resultats presentats amb Excel.
A17: 3. Patrons Co(II) | B17: Les dades ens han estat proporcionades ja que després de realitzar les regresions amb les obtingudes per nosaltres no es seguia correctament la llei de Labert Beer. És a dir, les desviacions estàndard per a la constant de proporcionalitat obtinguda a cada longitud d'ona eren de l'ordre del 20%
A19: concentració estoc | B19: 1000 | C19: mg/L
A20: conc. dissoluc. Intermèdia | B20: 1 | C20: mg/L
A22: Patró (mg/L Co2+) | B22: ml dissoluc. Interm. Co2+ | C22: ml enràs
A23: 0,3 | B23: 10 | C23: 25
A24: 0,4 | B24: 15 | C24: 25
A25: 0,5 | B25: 20 | C25: 25
A27: 4. Patrons Ni(II)
A29: concentració estoc | B29: 1000 | C29: mg/L
A30: conc. dissoluc. Intermèdia | B30: 1 | C30: mg/L
A32: Patró (mg/L Ni2+) | B32: ml dissoluc. Interm. Ni2+ | C32: ml enràs
A33: 0,3 | B33: 10 | C33: 25
A34: 0,4 | B34: 15 | C34: 25
A35: 0,5 | B35: 20 | C35: 25
A38: 5. Mostres
A40: conc. dissoluc. intermèdia Co2+ | B40: 1 | C40: mg/L
A41: conc. dissoluc. intermèdia Ni2+ | B41: 1 | C41: mg/L
A43: conc. Ni/Co (mg/L) | B43: ml dissoluc. interm. Ni2+ | C43: ml enràs | D43: ml dissoluc. interm. Co2+ | E43: ml enràs
A44: 0,2 / 0,4 | B44: 10 | C44: 50 | D44: 20 | E44: 50
A45: 0,4 / 0,4 | B45: 20 | C45: 50 | D45: 20 | E45: 50
A46: 0,4 / 0,2 | B46: 20 | C46: 50 | D46: 10 | E46: 50
A49: 6. Mesures absorbància
B51: Patrons Co2+ (mg/L) | E51: Patrons Ni2+ (mg/L) | H51: Mostres Ni/Co (mg/L)
A52: Longitud d'ona (nm) | B52: 0,3 | C52: 0,4 | D52: 0,5 | E52: 0,3 | F52: 0,4 | G52: 0,5 | H52: 0,2 / 0,4 | I52: 0,4 / 0,4 | J52: 0,4 / 0,2
A53: 480 | B53: 0.0809535 | C53: 0.0991025 | D53: 0.126627 | E53: 0.101215 | F53: 0.158284 | G53: 0.227642 | H53: 0.184298 | I53: 0.272768 | J53: 0.222974
A54: 485 | B54: 0.089074 | C54: 0.11087 | D54: 0.143126 | E54: 0.113828 | F54: 0.174151 | G54: 0.247608 | H54: 0.204836 | I54: 0.302884 | J54: 0.245325
A55: 490 | B55: 0.0965671 | C55: 0.121933 | D55: 0.15813 | E55: 0.125742 | F55: 0.189509 | G55: 0.266495 | H55: 0.223595 | I55: 0.330733 | J55: 0.266254
A56: 495 | B56: 0.103397 | C56: 0.131716 | D56: 0.172053 | E56: 0.135619 | F56: 0.201878 | G56: 0.281826 | H56: 0.240283 | I56: 0.354012 | J56: 0.283598
A57: 500 | B57: 0.109699 | C57: 0.140821 | D57: 0.184337 | E57: 0.142324 | F57: 0.209733 | G57: 0.290624 | H57: 0.253304 | I57: 0.370971 | J57: 0.29537
A58: 505 | B58: 0.11546 | C58: 0.149307 | D58: 0.19592 | E58: 0.146237 | F58: 0.212471 | G58: 0.293206 | H58: 0.263584 | I58: 0.382485 | J58: 0.302356
A59: 510 | B59: 0.120405 | C59: 0.156871 | D59: 0.205932 | E59: 0.14774 | F59: 0.212083 | G59: 0.291246 | H59: 0.271117 | I59: 0.389229 | J59: 0.305127
A60: 515 | B60: 0.124223 | C60: 0.162489 | D60: 0.213637 | E60: 0.148332 | F60: 0.210402 | G60: 0.287563 | H60: 0.27612 | I60: 0.392589 | J60: 0.305818
...

Sheet Solver
F1: 8.2.b. Mostra Ni/Co 0,2/0,4 (mg/L) | P1: 8.2.c. Mostra Ni/Co 0,4/0,2 (mg/L) | Y1: 8.1.d. Mostra Ni/Co 0,4/0,4 (mg/L)
B2: k mitjana | F2: Absorbància | P2: Absorbància | Y2: Absorbància
A3: lambda (nm) | B3: Níquel | C3: Cobalt | F3: Experimental | G3: Calculada | H3: Diferència | I3: Diferència^2 | J3: err. Rel | K3: cNi | L3: 0.21197824 | P3: Experimental | Q3: Calculada | R3: Diferència | S3: Diferència^2 | T3: err. Rel | U3: cNi | V3: 0.46033056 | Y3: Experimental | Z3: Calculada | AA3: Diferència | AB3: Diferència^2 | AC3: err. Rel | AD3: cNi | AE3: 0.47712715
A4: ='Pràctica A'!A196 -> 480 | B4: ='Pràctica A'!D196 -> 0.39612578 | C4: ='Pràctica A'!E196 -> 0.25695175 | F4: ='Pràctica A'!H53 -> 0.184298 | G4: =$L$5+$L$4*C4+$L$3*B4 -> 0.18463816 | H4: =G4-F4 -> 0.00034016091 | I4: =H4^2 -> 1.1570945e-07 | J4: =ABS(G4-F4)/F4*100 -> 0.18457114 | K4: cCo | L4: 0.39177828 | P4: ='Pràctica A'!J53 -> 0.222974 | Q4: =$V$5+$V$4*C4+$V$3*B4 -> 0.22280764 | R4: =Q4-P4 -> -0.00016636145 | S4: =R4^2 -> 2.7676133e-08 | T4: =ABS(Q4-P4)/P4*100 -> 0.074610248 | U4: cCo | V4: 0.12337091 | Y4: ='Pràctica A'!I53 -> 0.272768 | Z4: =$AE$5+$AE$4*C4+$AE$3*B4 -> 0.27399522 | AA4: =Z4-Y4 -> 0.0012272175 | AB4: =AA4^2 -> 1.5060629e-06 | AC4: =ABS(Z4-Y4)/Y4*100 -> 0.44991258 | AD4: cCo | AE4: 0.33077359
A5: ='Pràctica A'!A197 -> 485 | B5: ='Pràctica A'!D197 -> 0.43667339 | C5: ='Pràctica A'!E197 -> 0.28678011 | F5: ='Pràctica A'!H54 -> 0.204836 | G5: =$L$5+$L$4*C5+$L$3*B5 -> 0.20491948 | H5: =G5-F5 -> 8.3476262e-05 | I5: =H5^2 -> 6.9682863e-09 | J5: =ABS(G5-F5)/F5*100 -> 0.04075273 | K5: e | L5: 0 | P5: ='Pràctica A'!J54 -> 0.245325 | Q5: =$V$5+$V$4*C5+$V$3*B5 -> 0.2451529 | R5: =Q5-P5 -> -0.00017210477 | S5: =R5^2 -> 2.9620053e-08 | T5: =ABS(Q5-P5)/P5*100 -> 0.070153785 | U5: e | V5: 0.0087584652 | Y5: ='Pràctica A'!I54 -> 0.302884 | Z5: =$AE$5+$AE$4*C5+$AE$3*B5 -> 0.30320802 | AA5: =Z5-Y5 -> 0.00032401791 | AB5: =AA5^2 -> 1.0498761e-07 | AC5: =ABS(Z5-Y5)/Y5*100 -> 0.10697756 | AD5: e | AE5: 0
A6: ='Pràctica A'!A198 -> 490 | B6: ='Pràctica A'!D198 -> 0.47530083 | C6: ='Pràctica A'!E198 -> 0.31432761 | F6: ='Pràctica A'!H55 -> 0.223595 | G6: =$L$5+$L$4*C6+$L$3*B6 -> 0.22390017 | H6: =G6-F6 -> 0.00030516622 | I6: =H6^2 -> 9.3126419e-08 | J6: =ABS(G6-F6)/F6*100 -> 0.13648168 | K6: SS | L6: =SUM(I4:I18) -> 1.1328827e-06 | P6: ='Pràctica A'!J55 -> 0.266254 | Q6: =$V$5+$V$4*C6+$V$3*B6 -> 0.26633285 | R6: =Q6-P6 -> 7.8848596e-05 | S6: =R6^2 -> 6.2171011e-09 | T6: =ABS(Q6-P6)/P6*100 -> 0.029614051 | U6: SS | V6: =SUM(S4:S18) -> 3.3076729e-06 | Y6: ='Pràctica A'!I55 -> 0.330733 | Z6: =$AE$5+$AE$4*C6+$AE$3*B6 -> 0.33075021 | AA6: =Z6-Y6 -> 1.7206003e-05 | AB6: =AA6^2 -> 2.9604655e-10 | AC6: =ABS(Z6-Y6)/Y6*100 -> 0.0052023848 | AD6: SS | AE6: =SUM(AB4:AB18) -> 8.0627072e-06
A7: ='Pràctica A'!A199 -> 495 | B7: ='Pràctica A'!D199 -> 0.50680344 | C7: ='Pràctica A'!E199 -> 0.33935089 | F7: ='Pràctica A'!H56 -> 0.240283 | G7: =$L$5+$L$4*C7+$L$3*B7 -> 0.24038161 | H7: =G7-F7 -> 9.8611072e-05 | I7: =H7^2 -> 9.7241435e-09 | J7: =ABS(G7-F7)/F7*100 -> 0.041039554 | P7: ='Pràctica A'!J56 -> 0.283598 | Q7: =$V$5+$V$4*C7+$V$3*B7 -> 0.28392161 | R7: =Q7-P7 -> 0.00032360783 | S7: =R7^2 -> 1.0472203e-07 | T7: =ABS(Q7-P7)/P7*100 -> 0.11410794 | Y7: ='Pràctica A'!I56 -> 0.354012 | Z7: =$AE$5+$AE$4*C7+$AE$3*B7 -> 0.354058 | AA7: =Z7-Y7 -> 4.5996605e-05 | AB7: =AA7^2 -> 2.1156877e-09 | AC7: =ABS(Z7-Y7)/Y7*100 -> 0.012992951
A8: ='Pràctica A'!A200 -> 500 | B8: ='Pràctica A'!D200 -> 0.52666461 | C8: ='Pràctica A'!E200 -> 0.36212994 | F8: ='Pràctica A'!H57 -> 0.253304 | G8: =$L$5+$L$4*C8+$L$3*B8 -> 0.25351609 | H8: =G8-F8 -> 0.00021208545 | I8: =H8^2 -> 4.498024e-08 | J8: =ABS(G8-F8)/F8*100 -> 0.083727637 | P8: ='Pràctica A'!J57 -> 0.29537 | Q8: =$V$5+$V$4*C8+$V$3*B8 -> 0.29587458 | R8: =Q8-P8 -> 0.00050458264 | S8: =R8^2 -> 2.5460364e-07 | T8: =ABS(Q8-P8)/P8*100 -> 0.1708307 | Y8: ='Pràctica A'!I57 -> 0.370971 | Z8: =$AE$5+$AE$4*C8+$AE$3*B8 -> 0.37106901 | AA8: =Z8-Y8 -> 9.8008532e-05 | AB8: =AA8^2 -> 9.6056724e-09 | AC8: =ABS(Z8-Y8)/Y8*100 -> 0.026419459
A9: ='Pràctica A'!A201 -> 505 | B9: ='Pràctica A'!D201 -> 0.53501539 | C9: ='Pràctica A'!E201 -> 0.38332472 | F9: ='Pràctica A'!H58 -> 0.263584 | G9: =$L$5+$L$4*C9+$L$3*B9 -> 0.26358992 | H9: =G9-F9 -> 5.9221844e-06 | I9: =H9^2 -> 3.5072268e-11 | J9: =ABS(G9-F9)/F9*100 -> 0.0022467921 | P9: ='Pràctica A'!J58 -> 0.302356 | Q9: =$V$5+$V$4*C9+$V$3*B9 -> 0.30233352 | R9: =Q9-P9 -> -2.2480148e-05 | S9: =R9^2 -> 5.0535705e-10 | T9: =ABS(Q9-P9)/P9*100 -> 0.0074349931 | Y9: ='Pràctica A'!I58 -> 0.382485 | Z9: =$AE$5+$AE$4*C9+$AE$3*B9 -> 0.38206406 | AA9: =Z9-Y9 -> -0.00042093586 | AB9: =AA9^2 -> 1.77187e-07 | AC9: =ABS(Z9-Y9)/Y9*100 -> 0.11005291
A10: ='Pràctica A'!A202 -> 510 | B10: ='Pràctica A'!D202 -> 0.53505539 | C10: ='Pràctica A'!E202 -> 0.40179717 | F10: ='Pràctica A'!H59 -> 0.271117 | G10: =$L$5+$L$4*C10+$L$3*B10 -> 0.2708355 | H10: =G10-F10 -> -0.00028149623 | I10: =H10^2 -> 7.9240129e-08 | J10: =ABS(G10-F10)/F10*100 -> 0.10382832 | P10: ='Pràctica A'!J59 -> 0.305127 | Q10: =$V$5+$V$4*C10+$V$3*B10 -> 0.3046309 | R10: =Q10-P10 -> -0.0004961047 | S10: =R10^2 -> 2.4611987e-07 | T10: =ABS(Q10-P10)/P10*100 -> 0.16258958 | Y10: ='Pràctica A'!I59 -> 0.389229 | Z10: =$AE$5+$AE$4*C10+$AE$3*B10 -> 0.38819335 | AA10: =Z10-Y10 -> -0.001035654 | AB10: =AA10^2 -> 1.0725791e-06 | AC10: =ABS(Z10-Y10)/Y10*100 -> 0.26607831
A11: ='Pràctica A'!A203 -> 515 | B11: ='Pràctica A'!D203 -> 0.531857 | C11: ='Pràctica A'!E203 -> 0.41585772 | F11: ='Pràctica A'!H60 -> 0.27612 | G11: =$L$5+$L$4*C11+$L$3*B11 -> 0.27566614 | H11: =G11-F11 -> -0.00045386487 | I11: =H11^2 -> 2.0599332e-07 | J11: =ABS(G11-F11)/F11*100 -> 0.16437233 | P11: ='Pràctica A'!J60 -> 0.305818 | Q11: =$V$5+$V$4*C11+$V$3*B11 -> 0.30489324 | R11: =Q11-P11 -> -0.00092475736 | S11: =R11^2 -> 8.5517618e-07 | T11: =ABS(Q11-P11)/P11*100 -> 0.30238814 | Y11: ='Pràctica A'!I60 -> 0.392589 | Z11: =$AE$5+$AE$4*C11+$AE$3*B11 -> 0.39131817 | AA11: =Z11-Y11 -> -0.0012708317 | AB11: =AA11^2 -> 1.6150131e-06 | AC11: =ABS(Z11-Y11)/Y11*100 -> 0.32370536
A12: ='Pràctica A'!A204 -> 520 | B12: ='Pràctica A'!D204 -> 0.53050806 | C12: ='Pràctica A'!E204 -> 0.42403333 | F12: ='Pràctica A'!H61 -> 0.279159 | G12: =$L$5+$L$4*C12+$L$3*B12 -> 0.27858322 | H12: =G12-F12 -> -0.00057578491 | I12: =H12^2 -> 3.3152826e-07 | J12: =ABS(G12-F12)/F12*100 -> 0.20625698 | P12: ='Pràctica A'!J61 -> 0.306021 | Q12: =$V$5+$V$4*C12+$V$3*B12 -> 0.30528091 | R12: =Q12-P12 -> -0.00074008516 | S12: =R12^2 -> 5.4772605e-07 | T12: =ABS(Q12-P12)/P12*100 -> 0.2418413 | Y12: ='Pràctica A'!I61 -> 0.394476 | Z12: =$AE$5+$AE$4*C12+$AE$3*B12 -> 0.39337883 | AA12: =Z12-Y12 -> -0.0010971734 | AB12: =AA12^2 -> 1.2037895e-06 | AC12: =ABS(Z12-Y12)/Y12*100 -> 0.27813439
A13: ='Pràctica A'!A205 -> 525 | B13: ='Pràctica A'!D205 -> 0.53149944 | C13: ='Pràctica A'!E205 -> 0.42695733 | F13: ='Pràctica A'!H62 -> 0.28017 | G13: =$L$5+$L$4*C13+$L$3*B13 -> 0.27993893 | H13: =G13-F13 -> -0.00023107235 | I13: =H13^2 -> 5.3394433e-08 | J13: =ABS(G13-F13)/F13*100 -> 0.082475766 | P13: ='Pràctica A'!J62 -> 0.306065 | Q13: =$V$5+$V$4*C13+$V$3*B13 -> 0.30609802 | R13: =Q13-P13 -> 3.3017979e-05 | S13: =R13^2 -> 1.0901869e-09 | T13: =ABS(Q13-P13)/P13*100 -> 0.010787898 | Y13: ='Pràctica A'!I62 -> 0.394721 | Z13: =$AE$5+$AE$4*C13+$AE$3*B13 -> 0.39481903 | AA13: =Z13-Y13 -> 9.8027131e-05 | AB13: =AA13^2 -> 9.6093185e-09 | AC13: =ABS(Z13-Y13)/Y13*100 -> 0.024834537
A14: ='Pràctica A'!A206 -> 530 | B14: ='Pràctica A'!D206 -> 0.52526161 | C14: ='Pràctica A'!E206 -> 0.42446944 | F14: ='Pràctica A'!H63 -> 0.277649 | G14: =$L$5+$L$4*C14+$L$3*B14 -> 0.27764194 | H14: =G14-F14 -> -7.0581362e-06 | I14: =H14^2 -> 4.9817287e-11 | J14: =ABS(G14-F14)/F14*100 -> 0.0025421076 | P14: ='Pràctica A'!J63 -> 0.302216 | Q14: =$V$5+$V$4*C14+$V$3*B14 -> 0.30291962 | R14: =Q14-P14 -> 0.00070361953 | S14: =R14^2 -> 4.9508044e-07 | T14: =ABS(Q14-P14)/P14*100 -> 0.23282008 | Y14: ='Pràctica A'!I63 -> 0.390117 | Z14: =$AE$5+$AE$4*C14+$AE$3*B14 -> 0.39101986 | AA14: =Z14-Y14 -> 0.00090285953 | AB14: =AA14^2 -> 8.1515534e-07 | AC14: =ABS(Z14-Y14)/Y14*100 -> 0.23143301
A15: ='Pràctica A'!A207 -> 535 | B15: ='Pràctica A'!D207 -> 0.50119556 | C15: ='Pràctica A'!E207 -> 0.41851667 | F15: ='Pràctica A'!H64 -> 0.270083 | G15: =$L$5+$L$4*C15+$L$3*B15 -> 0.27020829 | H15: =G15-F15 -> 0.00012529263 | I15: =H15^2 -> 1.5698243e-08 | J15: =ABS(G15-F15)/F15*100 -> 0.046390417 | P15: ='Pràctica A'!J64 -> 0.290308 | Q15: =$V$5+$V$4*C15+$V$3*B15 -> 0.29110688 | R15: =Q15-P15 -> 0.000798879 | S15: =R15^2 -> 6.3820765e-07 | T15: =ABS(Q15-P15)/P15*100 -> 0.27518325 | Y15: ='Pràctica A'!I64 -> 0.376455 | Z15: =$AE$5+$AE$4*C15+$AE$3*B15 -> 0.37756827 | AA15: =Z15-Y15 -> 0.0011132693 | AB15: =AA15^2 -> 1.2393685e-06 | AC15: =ABS(Z15-Y15)/Y15*100 -> 0.2957244
A16: ='Pràctica A'!A208 -> 540 | B16: ='Pràctica A'!D208 -> 0.45877661 | C16: ='Pràctica A'!E208 -> 0.40979361 | F16: ='Pràctica A'!H65 -> 0.257577 | G16: =$L$5+$L$4*C16+$L$3*B16 -> 0.2577989 | H16: =G16-F16 -> 0.00022189557 | I16: =H16^2 -> 4.9237643e-08 | J16: =ABS(G16-F16)/F16*100 -> 0.086147275 | P16: ='Pràctica A'!J65 -> 0.27023 | Q16: =$V$5+$V$4*C16+$V$3*B16 -> 0.27050397 | R16: =Q16-P16 -> 0.00027397108 | S16: =R16^2 -> 7.5060154e-08 | T16: =ABS(Q16-P16)/P16*100 -> 0.10138441 | Y16: ='Pràctica A'!I65 -> 0.35389 | Z16: =$AE$5+$AE$4*C16+$AE$3*B16 -> 0.35444368 | AA16: =Z16-Y16 -> 0.00055368275 | AB16: =AA16^2 -> 3.0656458e-07 | AC16: =ABS(Z16-Y16)/Y16*100 -> 0.15645617
A17: ='Pràctica A'!A209 -> 545 | B17: ='Pràctica A'!D209 -> 0.40793622 | C17: ='Pràctica A'!E209 -> 0.39739661 | F17: ='Pràctica A'!H66 -> 0.242007 | G17: =$L$5+$L$4*C17+$L$3*B17 -> 0.24216496 | H17: =G17-F17 -> 0.00015796387 | I17: =H17^2 -> 2.4952584e-08 | J17: =ABS(G17-F17)/F17*100 -> 0.065272439 | P17: ='Pràctica A'!J66 -> 0.245724 | Q17: =$V$5+$V$4*C17+$V$3*B17 -> 0.24557116 | R17: =Q17-P17 -> -0.00015284297 | S17: =R17^2 -> 2.3360972e-08 | T17: =ABS(Q17-P17)/P17*100 -> 0.062201074 | Y17: ='Pràctica A'!I66 -> 0.326104 | Z17: =$AE$5+$AE$4*C17+$AE$3*B17 -> 0.32608575 | AA17: =Z17-Y17 -> -1.8247419e-05 | AB17: =AA17^2 -> 3.3296829e-10 | AC17: =ABS(Z17-Y17)/Y17*100 -> 0.0055955826
A18: ='Pràctica A'!A210 -> 550 | B18: ='Pràctica A'!D210 -> 0.35936772 | C18: ='Pràctica A'!E210 -> 0.38005328 | F18: ='Pràctica A'!H67 -> 0.224755 | G18: =$L$5+$L$4*C18+$L$3*B18 -> 0.22507476 | H18: =G18-F18 -> 0.00031975724 | I18: =H18^2 -> 1.0224469e-07 | J18: =ABS(G18-F18)/F18*100 -> 0.14226925 | P18: ='Pràctica A'!J67 -> 0.221124 | Q18: =$V$5+$V$4*C18+$V$3*B18 -> 0.22107393 | R18: =Q18-P18 -> -5.0070752e-05 | S18: =R18^2 -> 2.5070802e-09 | T18: =ABS(Q18-P18)/P18*100 -> 0.022643744 | Y18: ='Pràctica A'!I67 -> 0.297182 | Z18: =$AE$5+$AE$4*C18+$AE$3*B18 -> 0.29717569 | AA18: =Z18-Y18 -> -6.3141569e-06 | AB18: =AA18^2 -> 3.9868577e-11 | AC18: =ABS(Z18-Y18)/Y18*100 -> 0.0021246768
F20: Pre-solver: | P20: Pre-solver: | Y20: Pre-solver
B41: En tots els casos utilitzant el solver, observem que les diferències entre les absorbàncies calculades i experiemntals són totes del mateix ordrede magnitud, amb un error relatiu sempre inferior al 0,5%, així que no podem descartar cap dada.
B42: El problema que té aquest mètode és que no brinda una estimació de l'error per als resultats obtinguts ja que l'únic que fa és trobar els mínims quadrats i per tant no considera eines estadístiques més potents.
B43: Per altra banda però, té l'avantatge que si que permet fer fàcilment regresions amb tantes variables com es vulgui i de funcions no necessariament ni lineals ni polinòmiques

Sheet Matricial
A1: Mètode matricial:
B2: k mitjana
A3: lambda (nm) | B3: Níquel | C3: Cobalt | F3: Matriu K | I3: Matriu K^T
A4: ='Pràctica A'!A196 -> 480 | B4: ='Pràctica A'!D196 -> 0.39612578 | C4: ='Pràctica A'!E196 -> 0.25695175 | F4: =B4 -> 0.39612578 | G4: =C4 -> 0.25695175 | I4: {=TRANSPOSE(F4:G18)} -> 0.39612578 | J4: 0.43667339 | K4: 0.47530083 | L4: 0.50680344 | M4: 0.52666461 | N4: 0.53501539 | O4: 0.53505539 | P4: 0.531857 | Q4: 0.53050806 | R4: 0.53149944 | S4: 0.52526161 | T4: 0.50119556 | U4: 0.45877661 | V4: 0.40793622 | W4: 0.35936772
A5: ='Pràctica A'!A197 -> 485 | B5: ='Pràctica A'!D197 -> 0.43667339 | C5: ='Pràctica A'!E197 -> 0.28678011 | F5: =B5 -> 0.43667339 | G5: =C5 -> 0.28678011 | I5: 0.25695175 | J5: 0.28678011 | K5: 0.31432761 | L5: 0.33935089 | M5: 0.36212994 | N5: 0.38332472 | O5: 0.40179717 | P5: 0.41585772 | Q5: 0.42403333 | R5: 0.42695733 | S5: 0.42446944 | T5: 0.41851667 | U5: 0.40979361 | V5: 0.39739661 | W5: 0.38005328
A6: ='Pràctica A'!A198 -> 490 | B6: ='Pràctica A'!D198 -> 0.47530083 | C6: ='Pràctica A'!E198 -> 0.31432761 | F6: =B6 -> 0.47530083 | G6: =C6 -> 0.31432761
A7: ='Pràctica A'!A199 -> 495 | B7: ='Pràctica A'!D199 -> 0.50680344 | C7: ='Pràctica A'!E199 -> 0.33935089 | F7: =B7 -> 0.50680344 | G7: =C7 -> 0.33935089 | I7: Matriu K^T * K
A8: ='Pràctica A'!A200 -> 500 | B8: ='Pràctica A'!D200 -> 0.52666461 | C8: ='Pràctica A'!E200 -> 0.36212994 | F8: =B8 -> 0.52666461 | G8: =C8 -> 0.36212994 | I8: {=MMULT(_xlfn.ANCHORARRAY(I4),F4:G18)} -> 3.5601934 | J8: 2.751657
A9: ='Pràctica A'!A201 -> 505 | B9: ='Pràctica A'!D201 -> 0.53501539 | C9: ='Pràctica A'!E201 -> 0.38332472 | F9: =B9 -> 0.53501539 | G9: =C9 -> 0.38332472 | I9: 2.751657 | J9: 2.1624052
A10: ='Pràctica A'!A202 -> 510 | B10: ='Pràctica A'!D202 -> 0.53505539 | C10: ='Pràctica A'!E202 -> 0.40179717 | F10: =B10 -> 0.53505539 | G10: =C10 -> 0.40179717
A11: ='Pràctica A'!A203 -> 515 | B11: ='Pràctica A'!D203 -> 0.531857 | C11: ='Pràctica A'!E203 -> 0.41585772 | F11: =B11 -> 0.531857 | G11: =C11 -> 0.41585772 | I11: Matriu (K^T * K)^-1
A12: ='Pràctica A'!A204 -> 520 | B12: ='Pràctica A'!D204 -> 0.53050806 | C12: ='Pràctica A'!E204 -> 0.42403333 | F12: =B12 -> 0.53050806 | G12: =C12 -> 0.42403333 | I12: {=MINVERSE(_xlfn.ANCHORARRAY(I8))} -> 17.031607 | J12: -21.672692
A13: ='Pràctica A'!A205 -> 525 | B13: ='Pràctica A'!D205 -> 0.53149944 | C13: ='Pràctica A'!E205 -> 0.42695733 | F13: =B13 -> 0.53149944 | G13: =C13 -> 0.42695733 | I13: -21.672692 | J13: 28.040913
A14: ='Pràctica A'!A206 -> 530 | B14: ='Pràctica A'!D206 -> 0.52526161 | C14: ='Pràctica A'!E206 -> 0.42446944 | F14: =B14 -> 0.52526161 | G14: =C14 -> 0.42446944
A15: ='Pràctica A'!A207 -> 535 | B15: ='Pràctica A'!D207 -> 0.50119556 | C15: ='Pràctica A'!E207 -> 0.41851667 | F15: =B15 -> 0.50119556 | G15: =C15 -> 0.41851667 | I15: Pseudoinversa sencera: (K^T * K)^-1 K^T
A16: ='Pràctica A'!A208 -> 540 | B16: ='Pràctica A'!D208 -> 0.45877661 | C16: ='Pràctica A'!E208 -> 0.40979361 | F16: =B16 -> 0.45877661 | G16: =C16 -> 0.40979361 | I16: {=MMULT(_xlfn.ANCHORARRAY(I12),_xlfn.ANCHORARRAY(I4))} -> 1.1778224 | J16: 1.2219525 | K16: 1.2828115 | L16: 1.2770298 | M16: 1.1216139 | N16: 0.80449321 | O16: 0.40482687 | P16: 0.045623084 | Q16: -0.15453911 | R16: -0.20102511 | S16: -0.25334619 | T16: -0.53421707 | U16: -1.0676278 | V16: -1.6648449 | W16: -2.1161678
A17: ='Pràctica A'!A209 -> 545 | B17: ='Pràctica A'!D209 -> 0.40793622 | C17: ='Pràctica A'!E209 -> 0.39739661 | F17: =B17 -> 0.40793622 | G17: =C17 -> 0.39739661 | I17: -1.3799503 | J17: -1.4223117 | K17: -1.4870153 | L17: -1.4680862 | M17: -1.2597856 | N17: -0.84644853 | O17: -0.32933123 | P17: 0.13425728 | Q17: 0.39274414 | R17: 0.4532497 | S17: 0.51867767 | T17: 0.87333255 | U17: 1.5480628 | V17: 2.3022877 | W17: 2.8685749
A18: ='Pràctica A'!A210 -> 550 | B18: ='Pràctica A'!D210 -> 0.35936772 | C18: ='Pràctica A'!E210 -> 0.38005328 | F18: =B18 -> 0.35936772 | G18: =C18 -> 0.38005328
A20: Amb aquests valors calculats, ja podem resoldre el sistema d'equacions amb les absorbàncies experimentals.
A21: Mostres Ni/Co mg/L | F21: Vectors de concentracions per Ni/Co mg/L:
A22: ='Pràctica A'!H52 -> 0,2 / 0,4 | B22: ='Pràctica A'!I52 -> 0,4 / 0,4 | C22: ='Pràctica A'!J52 -> 0,4 / 0,2 | F22: =A22 -> 0,2 / 0,4 | G22: =B22 -> 0,4 / 0,4 | H22: =C22 -> 0,4 / 0,2
A23: ='Pràctica A'!H53 -> 0.184298 | B23: ='Pràctica A'!I53 -> 0.272768 | C23: ='Pràctica A'!J53 -> 0.222974 | E23: c_Níquel | F23: {=MMULT(_xlfn.ANCHORARRAY(I16),A23:A37)} -> 0.21195647 | G23: {=MMULT(_xlfn.ANCHORARRAY(I16),B23:B37)} -> 0.47713191 | H23: {=MMULT(_xlfn.ANCHORARRAY(I16),C23:C37)} -> 0.47212188
A24: ='Pràctica A'!H54 -> 0.204836 | B24: ='Pràctica A'!I54 -> 0.302884 | C24: ='Pràctica A'!J54 -> 0.245325 | E24: c_Cobalt | F24: 0.39180607 | G24: 0.33076669 | H24: 0.13121811
A25: ='Pràctica A'!H55 -> 0.223595 | B25: ='Pràctica A'!I55 -> 0.330733 | C25: ='Pràctica A'!J55 -> 0.266254
A26: ='Pràctica A'!H56 -> 0.240283 | B26: ='Pràctica A'!I56 -> 0.354012 | C26: ='Pràctica A'!J56 -> 0.283598 | F26: Calculats com Pseudoinversa*A
A27: ='Pràctica A'!H57 -> 0.253304 | B27: ='Pràctica A'!I57 -> 0.370971 | C27: ='Pràctica A'!J57 -> 0.29537
A28: ='Pràctica A'!H58 -> 0.263584 | B28: ='Pràctica A'!I58 -> 0.382485 | C28: ='Pràctica A'!J58 -> 0.302356
A29: ='Pràctica A'!H59 -> 0.271117 | B29: ='Pràctica A'!I59 -> 0.389229 | C29: ='Pràctica A'!J59 -> 0.305127
A30: ='Pràctica A'!H60 -> 0.27612 | B30: ='Pràctica A'!I60 -> 0.392589 | C30: ='Pràctica A'!J60 -> 0.305818
A31: ='Pràctica A'!H61 -> 0.279159 | B31: ='Pràctica A'!I61 -> 0.394476 | C31: ='Pràctica A'!J61 -> 0.306021
A32: ='Pràctica A'!H62 -> 0.28017 | B32: ='Pràctica A'!I62 -> 0.394721 | C32: ='Pràctica A'!J62 -> 0.306065
A33: ='Pràctica A'!H63 -> 0.277649 | B33: ='Pràctica A'!I63 -> 0.390117 | C33: ='Pràctica A'!J63 -> 0.302216
A34: ='Pràctica A'!H64 -> 0.270083 | B34: ='Pràctica A'!I64 -> 0.376455 | C34: ='Pràctica A'!J64 -> 0.290308
A35: ='Pràctica A'!H65 -> 0.257577 | B35: ='Pràctica A'!I65 -> 0.35389 | C35: ='Pràctica A'!J65 -> 0.27023
A36: ='Pràctica A'!H66 -> 0.242007 | B36: ='Pràctica A'!I66 -> 0.326104 | C36: ='Pràctica A'!J66 -> 0.245724
A37: ='Pràctica A'!H67 -> 0.224755 | B37: ='Pràctica A'!I67 -> 0.297182 | C37: ='Pràctica A'!J67 -> 0.221124
A39: El problema d'aquest mètode és que no és possible veure si cal descartar algun valor, en quant a la resta, funciona bé!

Sheet Càlculs
