Workbook

Sheet Pràctica A
A1: Informe pràctica F | E1: Data: | F1: 45776
A2: Grup pràctiques: | B2: 1.2 (G2) Matí - 1r torn | E2: Parella: | F2: M_01
A3: Alumnes: | B3: Gerard Moreno Mas i Òscar Losada Garcia
A5: 1. Descripció de les mostres
A6: Les mostres són mescles binàries de solucions ja preparades de Ni(II) i Co(II). Aquestes s'han preparat a partir de les sals Co(NO3)2·6H2O i Ni(NO3)2·6H2O, respectivament.
A9: 2. Instrumentació
A10: L'equip és un espectrofotòmetre Jasco V-730 de doble feix.
A17: 3. Patrons Co(II) | B17: A causa de l'aturada elèctrica no vam poder fer la pràctica i les dades d'absorbància ens han estat proporcionades pel Xavier.
A19: concentració estoc | B19: - | C19: mg/L
A20: conc. dissoluc. Intermèdia | B20: - | C20: mg/L
A22: Patró (mg/L Co2+) | B22: ml dissoluc. Interm. Co2+ | C22: ml enràs
A23: 0,3 | B23: - | C23: -
A24: 0,4 | B24: - | C24: -
A25: 0,5 | B25: - | C25: -
A27: 4. Patrons Ni(II)
A29: concentració estoc | B29: - | C29: mg/L
A30: conc. dissoluc. Intermèdia | B30: - | C30: mg/L
A32: Patró (mg/L Ni2+) | B32: ml dissoluc. Interm. Ni2+ | C32: ml enràs
A33: 0,3 | B33: - | C33: -
A34: 0,4 | B34: - | C34: -
A35: 0,5 | B35: - | C35: -
A38: 5. Mostres
A40: conc. dissoluc. intermèdia Co2+ | B40: - | C40: mg/L
A41: conc. dissoluc. intermèdia Ni2+ | B41: - | C41: mg/L
A43: conc. Ni/Co (mg/L) | B43: ml dissoluc. interm. Ni2+ | C43: ml enràs | D43: ml dissoluc. interm. Co2+ | E43: ml enràs
A44: 0,2 / 0,4 | B44: - | C44: - | D44: - | E44: -
A45: 0,4 / 0,4 | B45: - | C45: - | D45: - | E45: -
A46: 0,4 / 0,2 | B46: - | C46: - | D46: - | E46: -
A49: 6. Mesures absorbància
B51: Patrons Co2+ (mg/L) | E51: Patrons Ni2+ (mg/L) | H51: Mostres Ni / Co (mg/L)
A52: Longitud d'ona (nm) | B52: 0.3 | C52: 0.4 | D52: 0.5 | E52: 0.3 | F52: 0.4 | G52: 0.5 | H52: 0,2 / 0,4 (mg/mL) | I52: 0,4 / 0,4 (mg/mL) | J52: 0,4 / 0,2 (mg/mL)
A53: 550 | B53: 0.112216 | C53: 0.149505 | D53: 0.196172 | E53: 0.107048 | F53: 0.139749 | G53: 0.185952 | H53: 0.224755 | I53: 0.297182 | J53: 0.221124
A54: 545 | B54: 0.117358 | C54: 0.156241 | D54: 0.205197 | E54: 0.119768 | F54: 0.159388 | G54: 0.213056 | H54: 0.242007 | I54: 0.326104 | J54: 0.245724
A55: 540 | B55: 0.121135 | C55: 0.160983 | D55: 0.21157 | E55: 0.133105 | F55: 0.179909 | G55: 0.241437 | H55: 0.257577 | I55: 0.35389 | J55: 0.27023
A56: 535 | B56: 0.12378 | C56: 0.164272 | D56: 0.216135 | E56: 0.144155 | F56: 0.197072 | G56: 0.265195 | H56: 0.270083 | I56: 0.376455 | J56: 0.290308
A57: 530 | B57: 0.125761 | C57: 0.166382 | D57: 0.219125 | E57: 0.15001 | F57: 0.206915 | G57: 0.279232 | H57: 0.277649 | I57: 0.390117 | J57: 0.302216
A58: 525 | B58: 0.126768 | C58: 0.167188 | D58: 0.220171 | E58: 0.150826 | F58: 0.20959 | G58: 0.283885 | H58: 0.28017 | I58: 0.394721 | J58: 0.306065
A59: 520 | B59: 0.126213 | C59: 0.16588 | D59: 0.218345 | E59: 0.149345 | F59: 0.209483 | G59: 0.285 | H59: 0.279159 | I59: 0.394476 | J59: 0.306021
A60: 515 | B60: 0.124223 | C60: 0.162489 | D60: 0.213637 | E60: 0.148332 | F60: 0.210402 | G60: 0.287563 | H60: 0.27612 | I60: 0.392589 | J60: 0.305818
A61: 510 | B61: 0.120405 | C61: 0.156871 | D61: 0.205932 | E61: 0.14774 | F61: 0.212083 | G61: 0.291246 | H61: 0.271117 | I61: 0.389229 | J61: 0.305127
...

Sheet Solver
A2: k1 niquel | B2: k2 cobalt | D2: 8.1.b. Mostra Ni/Co 0,4/0,2 (mg/L)
A3: promig | B3: promig
A4: ='Pràctica A'!E118 -> 0.35936772 | B4: ='Pràctica A'!F118 -> 0.38005328 | D4: exp | E4: λ (nm) | F4: calculat | G4: c1 | H4: c2 | I4: e | J4: dif | K4: dif^2 | L4: suma | N4: Els paràmetres inicials eren 0,4 per C1 (Ni) i 0,2 per a C2 (Co); 0,04 per la e
A5: ='Pràctica A'!E119 -> 0.39884833 | B5: ='Pràctica A'!F119 -> 0.39739661 | D5: ='Pràctica A'!J53 -> 0.221124 | E5: 550 | F5: =A4*$G$5 + B4*$H$5 +$I$5 -> 0.22269196 | G5: 0.4497736 | H5: 0.13118061 | I5: 0.011202223 | J5: =D5-F5 -> -0.0015679574 | K5: =J5^2 -> 2.4584903e-06 | L5: =SUM(K5:K19) -> 1.6487392e-05
A6: ='Pràctica A'!E120 -> 0.45877661 | B6: ='Pràctica A'!F120 -> 0.40979361 | D6: ='Pràctica A'!J54 -> 0.245724 | E6: 545 | F6: =A5*$G$5 + B5*$H$5 +$I$5 -> 0.2427244 | J6: =D6-F6 -> 0.0029995969 | K6: =J6^2 -> 8.9975817e-06
A7: ='Pràctica A'!E121 -> 0.50119556 | B7: ='Pràctica A'!F121 -> 0.41851667 | D7: ='Pràctica A'!J55 -> 0.27023 | E7: 540 | F7: =A6*$G$5 + B6*$H$5 +$I$5 -> 0.27130481 | J7: =D7-F7 -> -0.0010748065 | K7: =J7^2 -> 1.155209e-06
A8: ='Pràctica A'!E122 -> 0.52526161 | B8: ='Pràctica A'!F122 -> 0.42446944 | D8: ='Pràctica A'!J56 -> 0.290308 | E8: 535 | F8: =A7*$G$5 + B7*$H$5 +$I$5 -> 0.29152802 | J8: =D8-F8 -> -0.0012200237 | K8: =J8^2 -> 1.4884578e-06
A9: ='Pràctica A'!E123 -> 0.53149944 | B9: ='Pràctica A'!F123 -> 0.42695733 | D9: ='Pràctica A'!J57 -> 0.302216 | E9: 530 | F9: =A8*$G$5 + B8*$H$5 +$I$5 -> 0.30313319 | J9: =D9-F9 -> -0.00091718922 | K9: =J9^2 -> 8.4123606e-07
A10: ='Pràctica A'!E124 -> 0.53050806 | B10: ='Pràctica A'!F124 -> 0.42403333 | D10: ='Pràctica A'!J58 -> 0.306065 | E10: 525 | F10: =A9*$G$5 + B9*$H$5 +$I$5 -> 0.30626516 | J10: =D10-F10 -> -0.00020016477 | K10: =J10^2 -> 4.0065933e-08
A11: ='Pràctica A'!E125 -> 0.531857 | B11: ='Pràctica A'!F125 -> 0.41585772 | D11: ='Pràctica A'!J59 -> 0.306021 | E11: 520 | F11: =A10*$G$5 + B10*$H$5 +$I$5 -> 0.30543569 | J11: =D11-F11 -> 0.00058530788 | K11: =J11^2 -> 3.4258532e-07
A12: ='Pràctica A'!E126 -> 0.53505539 | B12: ='Pràctica A'!F126 -> 0.40179717 | D12: ='Pràctica A'!J60 -> 0.305818 | E12: 515 | F12: =A11*$G$5 + B11*$H$5 +$I$5 -> 0.30496993 | J12: =D12-F12 -> 0.0008480699 | K12: =J12^2 -> 7.1922256e-07
A13: ='Pràctica A'!E127 -> 0.53501539 | B13: ='Pràctica A'!F127 -> 0.38332472 | D13: ='Pràctica A'!J61 -> 0.305127 | E13: 510 | F13: =A12*$G$5 + B12*$H$5 +$I$5 -> 0.30456401 | J13: =D13-F13 -> 0.00056299122 | K13: =J13^2 -> 3.1695911e-07
A14: ='Pràctica A'!E128 -> 0.52666461 | B14: ='Pràctica A'!F128 -> 0.36212994 | D14: ='Pràctica A'!J62 -> 0.302356 | E14: 505 | F14: =A13*$G$5 + B13*$H$5 +$I$5 -> 0.30212279 | J14: =D14-F14 -> 0.00023320863 | K14: =J14^2 -> 5.4386266e-08
A15: ='Pràctica A'!E129 -> 0.50680344 | B15: ='Pràctica A'!F129 -> 0.33935089 | D15: ='Pràctica A'!J63 -> 0.29537 | E15: 500 | F15: =A14*$G$5 + B14*$H$5 +$I$5 -> 0.29558649 | J15: =D15-F15 -> -0.00021648815 | K15: =J15^2 -> 4.6867118e-08
A16: ='Pràctica A'!E130 -> 0.47530083 | B16: ='Pràctica A'!F130 -> 0.31432761 | D16: ='Pràctica A'!J64 -> 0.283598 | E16: 495 | F16: =A15*$G$5 + B15*$H$5 +$I$5 -> 0.28366529 | J16: =D16-F16 -> -6.7289324e-05 | K16: =J16^2 -> 4.5278531e-09
A17: ='Pràctica A'!E131 -> 0.43667339 | B17: ='Pràctica A'!F131 -> 0.28678011 | D17: ='Pràctica A'!J65 -> 0.266254 | E17: 490 | F17: =A16*$G$5 + B16*$H$5 +$I$5 -> 0.26621368 | J17: =D17-F17 -> 4.0322347e-05 | K17: =J17^2 -> 1.6258917e-09
A18: ='Pràctica A'!E132 -> 0.39612578 | B18: ='Pràctica A'!F132 -> 0.25695175 | D18: ='Pràctica A'!J66 -> 0.245325 | E18: 485 | F18: =A17*$G$5 + B17*$H$5 +$I$5 -> 0.24522638 | J18: =D18-F18 -> 9.8624982e-05 | K18: =J18^2 -> 9.726887e-09
D19: ='Pràctica A'!J67 -> 0.222974 | E19: 480 | F19: =A18*$G$5 + B18*$H$5 +$I$5 -> 0.22307623 | J19: =D19-F19 -> -0.00010222736 | K19: =J19^2 -> 1.0450433e-08 | N19: Observem que el penúltim punt (545 nm) després de fer el solver no
N20: s'acaba d'ajustar bé, però en esborrar-lo el resultat és encara pitjor.
N21: Així que no esborrem cap punt.
D23: 8.1.c. Mostra Ni/Co 0,4/0,4 (mg/L)
G25: SOLVER
D26: exp | E26: λ (nm) | F26: calculat | G26: c1 | H26: c2 | I26: e | J26: dif | K26: dif^2 | L26: suma | N26: Els paràmetres inicials eren 0,4 per C1 (Ni) i 0,4 per a C2 (Co); 0,04 per la e
D27: ='Pràctica A'!I53 -> 0.297182 | E27: 550 | F27: =A4*$G$27 + B4*$H$27 +$I$27 -> 0.29841862 | G27: 0.46951904 | H27: 0.34123803 | I27: 0 | J27: =D27-F27 -> -0.0012366202 | K27: =J27^2 -> 1.5292294e-06 | L27: =SUM(K27:K41) -> 2.2154601e-05
D28: ='Pràctica A'!I54 -> 0.326104 | E28: 545 | F28: =A5*$G$27 + B5*$H$27 +$I$27 -> 0.32287372 | J28: =D28-F28 -> 0.0032302762 | K28: =J28^2 -> 1.0434684e-05
D29: ='Pràctica A'!I55 -> 0.35389 | E29: 540 | F29: =A6*$G$27 + B6*$H$27 +$I$27 -> 0.35524152 | J29: =D29-F29 -> -0.0013515194 | K29: =J29^2 -> 1.8266046e-06
D30: ='Pràctica A'!I56 -> 0.376455 | E30: 535 | F30: =A7*$G$27 + B7*$H$27 +$I$27 -> 0.37813466 | J30: =D30-F30 -> -0.0016796599 | K30: =J30^2 -> 2.8212574e-06
D31: ='Pràctica A'!I57 -> 0.390117 | E31: 530 | F31: =A8*$G$27 + B8*$H$27 +$I$27 -> 0.39146545 | J31: =D31-F31 -> -0.0013484455 | K31: =J31^2 -> 1.8183052e-06
D32: ='Pràctica A'!I58 -> 0.394721 | E32: 525 | F32: =A9*$G$27 + B9*$H$27 +$I$27 -> 0.39524319 | J32: =D32-F32 -> -0.00052218932 | K32: =J32^2 -> 2.7268168e-07
D33: ='Pràctica A'!I59 -> 0.394476 | E33: 520 | F33: =A10*$G$27 + B10*$H$27 +$I$27 -> 0.39377993 | J33: =D33-F33 -> 0.00069606664 | K33: =J33^2 -> 4.8450876e-07
D34: ='Pràctica A'!I60 -> 0.392589 | E34: 515 | F34: =A11*$G$27 + B11*$H$27 +$I$27 -> 0.39162346 | J34: =D34-F34 -> 0.00096554093 | K34: =J34^2 -> 9.3226929e-07
D35: ='Pràctica A'!I61 -> 0.389229 | E35: 510 | F35: =A12*$G$27 + B12*$H$27 +$I$27 -> 0.38832717 | J35: =D35-F35 -> 0.00090183266 | K35: =J35^2 -> 8.1330215e-07
D36: ='Pràctica A'!I62 -> 0.382485 | E36: 505 | F36: =A13*$G$27 + B13*$H$27 +$I$27 -> 0.38200489 | J36: =D36-F36 -> 0.00048011391 | K36: =J36^2 -> 2.3050937e-07
D37: ='Pràctica A'!I63 -> 0.370971 | E37: 500 | F37: =A14*$G$27 + B14*$H$27 +$I$27 -> 0.37085157 | J37: =D37-F37 -> 0.00011942726 | K37: =J37^2 -> 1.4262869e-08
D38: ='Pràctica A'!I64 -> 0.354012 | E38: 495 | F38: =A15*$G$27 + B15*$H$27 +$I$27 -> 0.3537533 | J38: =D38-F38 -> 0.00025870322 | K38: =J38^2 -> 6.6927357e-08
D39: ='Pràctica A'!I65 -> 0.330733 | E39: 490 | F39: =A16*$G$27 + B16*$H$27 +$I$27 -> 0.33042333 | J39: =D39-F39 -> 0.00030967303 | K39: =J39^2 -> 9.5897383e-08
D40: ='Pràctica A'!I66 -> 0.302884 | E40: 485 | F40: =A17*$G$27 + B17*$H$27 +$I$27 -> 0.30288675 | J40: =D40-F40 -> -2.7516191e-06 | K40: =J40^2 -> 7.5714076e-12
D41: ='Pràctica A'!I67 -> 0.272768 | E41: 480 | F41: =A18*$G$27 + B18*$H$27 +$I$27 -> 0.2736703 | J41: =D41-F41 -> -0.0009023049 | K41: =J41^2 -> 8.1415413e-07 | N41: Els punts experimentals i calculats se superposen bé al gràfic.
N42: No descartem cap punt.
D46: 8.1.d. Mostra Ni/Co 0,2/0,4 (mg/L)
...

Sheet Matricial
A2: {='Pràctica A'!A51:J67} -> 0 | B2: Patrons Co2+ (mg/L) | C2: 0 | D2: 0 | E2: Patrons Ni2+ (mg/L) | F2: 0 | G2: 0 | H2: Mostres Ni / Co (mg/L) | I2: 0 | J2: 0 | L2: {='Pràctica A'!A94:K110} -> 0 | M2: Patrons Co2+ (mg/L) | N2: 0 | O2: 0 | P2: 0 | Q2: 0 | R2: Patrons Ni2+ (mg/L) | S2: 0 | T2: 0 | U2: 0 | V2: 0
A3: Longitud d'ona (nm) | B3: 0.3 | C3: 0.4 | D3: 0.5 | E3: 0.3 | F3: 0.4 | G3: 0.5 | H3: 0,2 / 0,4 (mg/mL) | I3: 0,4 / 0,4 (mg/mL) | J3: 0,4 / 0,2 (mg/mL) | L3: Longitud d'ona (nm) | M3: 0,3 | N3: 0,4 | O3: 0,5 | P3: promig | Q3: std | R3: 0,3 | S3: 0,4 | T3: 0,5 | U3: promig | V3: std
A4: 550 | B4: 0.112216 | C4: 0.149505 | D4: 0.196172 | E4: 0.107048 | F4: 0.139749 | G4: 0.185952 | H4: 0.224755 | I4: 0.297182 | J4: 0.221124 | L4: 550 | M4: 0.37405333 | N4: 0.3737625 | O4: 0.392344 | P4: 0.38005328 | Q4: 0.010645071 | R4: 0.35682667 | S4: 0.3493725 | T4: 0.371904 | U4: 0.35936772 | V4: 0.011478669
A5: 545 | B5: 0.117358 | C5: 0.156241 | D5: 0.205197 | E5: 0.119768 | F5: 0.159388 | G5: 0.213056 | H5: 0.242007 | I5: 0.326104 | J5: 0.245724 | L5: 545 | M5: 0.39119333 | N5: 0.3906025 | O5: 0.410394 | P5: 0.39739661 | Q5: 0.011259945 | R5: 0.39922667 | S5: 0.39847 | T5: 0.426112 | U5: 0.39884833 | V5: 0.00053504413
A6: 540 | B6: 0.121135 | C6: 0.160983 | D6: 0.21157 | E6: 0.133105 | F6: 0.179909 | G6: 0.241437 | H6: 0.257577 | I6: 0.35389 | J6: 0.27023 | L6: 540 | M6: 0.40378333 | N6: 0.4024575 | O6: 0.42314 | P6: 0.40979361 | Q6: 0.011577307 | R6: 0.44368333 | S6: 0.4497725 | T6: 0.482874 | U6: 0.45877661 | V6: 0.02108987
A7: 535 | B7: 0.12378 | C7: 0.164272 | D7: 0.216135 | E7: 0.144155 | F7: 0.197072 | G7: 0.265195 | H7: 0.270083 | I7: 0.376455 | J7: 0.290308 | L7: 535 | M7: 0.4126 | N7: 0.41068 | O7: 0.43227 | P7: 0.41851667 | Q7: 0.011949361 | R7: 0.48051667 | S7: 0.49268 | T7: 0.53039 | U7: 0.50119556 | V7: 0.026004295
A8: 530 | B8: 0.125761 | C8: 0.166382 | D8: 0.219125 | E8: 0.15001 | F8: 0.206915 | G8: 0.279232 | H8: 0.277649 | I8: 0.390117 | J8: 0.302216 | L8: 530 | M8: 0.41920333 | N8: 0.415955 | O8: 0.43825 | P8: 0.42446944 | Q8: 0.012044322 | R8: 0.50003333 | S8: 0.5172875 | T8: 0.558464 | U8: 0.52526161 | V8: 0.030020419
A9: 525 | B9: 0.126768 | C9: 0.167188 | D9: 0.220171 | E9: 0.150826 | F9: 0.20959 | G9: 0.283885 | H9: 0.28017 | I9: 0.394721 | J9: 0.306065 | L9: 525 | M9: 0.42256 | N9: 0.41797 | O9: 0.440342 | P9: 0.42695733 | Q9: 0.011816472 | R9: 0.50275333 | S9: 0.523975 | T9: 0.56777 | U9: 0.53149944 | V9: 0.03315501
A10: 520 | B10: 0.126213 | C10: 0.16588 | D10: 0.218345 | E10: 0.149345 | F10: 0.209483 | G10: 0.285 | H10: 0.279159 | I10: 0.394476 | J10: 0.306021 | L10: 520 | M10: 0.42071 | N10: 0.4147 | O10: 0.43669 | P10: 0.42403333 | Q10: 0.011365449 | R10: 0.49781667 | S10: 0.5237075 | T10: 0.57 | U10: 0.53050806 | V10: 0.036569032
A11: 515 | B11: 0.124223 | C11: 0.162489 | D11: 0.213637 | E11: 0.148332 | F11: 0.210402 | G11: 0.287563 | H11: 0.27612 | I11: 0.392589 | J11: 0.305818 | L11: 515 | M11: 0.41407667 | N11: 0.4062225 | O11: 0.427274 | P11: 0.41585772 | Q11: 0.010638164 | R11: 0.49444 | S11: 0.526005 | T11: 0.575126 | U11: 0.531857 | V11: 0.04066008
A12: 510 | B12: 0.120405 | C12: 0.156871 | D12: 0.205932 | E12: 0.14774 | F12: 0.212083 | G12: 0.291246 | H12: 0.271117 | I12: 0.389229 | J12: 0.305127 | L12: 510 | M12: 0.40135 | N12: 0.3921775 | O12: 0.411864 | P12: 0.40179717 | Q12: 0.0098508649 | R12: 0.49246667 | S12: 0.5302075 | T12: 0.582492 | U12: 0.53505539 | V12: 0.045208038
A13: 505 | B13: 0.11546 | C13: 0.149307 | D13: 0.19592 | E13: 0.146237 | F13: 0.212471 | G13: 0.293206 | H13: 0.263584 | I13: 0.382485 | J13: 0.302356 | L13: 505 | M13: 0.38486667 | N13: 0.3732675 | O13: 0.39184 | P13: 0.38332472 | Q13: 0.0093817713 | R13: 0.48745667 | S13: 0.5311775 | T13: 0.586412 | U13: 0.53501539 | V13: 0.049589178
A14: 500 | B14: 0.109699 | C14: 0.140821 | D14: 0.184337 | E14: 0.142324 | F14: 0.209733 | G14: 0.290624 | H14: 0.253304 | I14: 0.370971 | J14: 0.29537 | L14: 500 | M14: 0.36566333 | N14: 0.3520525 | O14: 0.368674 | P14: 0.36212994 | Q14: 0.0088561952 | R14: 0.47441333 | S14: 0.5243325 | T14: 0.581248 | U14: 0.52666461 | V14: 0.053455501
A15: 495 | B15: 0.103397 | C15: 0.131716 | D15: 0.172053 | E15: 0.135619 | F15: 0.201878 | G15: 0.281826 | H15: 0.240283 | I15: 0.354012 | J15: 0.283598 | L15: 495 | M15: 0.34465667 | N15: 0.32929 | O15: 0.344106 | P15: 0.33935089 | Q15: 0.0087173346 | R15: 0.45206333 | S15: 0.504695 | T15: 0.563652 | U15: 0.50680344 | V15: 0.055824204
... A18: 480 | B18: 0.0809535 | C18: 0.0991025 | D18: 0.126627 | E18: 0.101215 | F18: 0.158284 | G18: 0.227642 | H18: 0.184298 | I18: 0.272768 | J18: 0.222974 | L18: 480 | M18: 0.269845 | N18: 0.24775625 | O18: 0.253254 | P18: 0.25695175 | Q18: 0.011499271 | R18: 0.33738333 | S18: 0.39571 | T18: 0.455284 | U18: 0.39612578 | V18: 0.058951433
A20: λ (nm) | B20: c1 és Ni | C20: Matriu K | F20: Matriu Kt
A21: 550 | B21: c2 és Co | C21: =U4 -> 0.35936772 | D21: =P4 -> 0.38005328 | F21: {=TRANSPOSE(C21:D35)} -> 0.35936772 | G21: 0.39884833 | H21: 0.45877661 | I21: 0.50119556 | J21: 0.52526161 | K21: 0.53149944 | L21: 0.53050806 | M21: 0.531857 | N21: 0.53505539 | O21: 0.53501539 | P21: 0.52666461 | Q21: 0.50680344 | R21: 0.47530083 | S21: 0.43667339 | T21: 0.39612578
A22: 545 | C22: =U5 -> 0.39884833 | D22: =P5 -> 0.39739661 | E22: Kt = | F22: 0.38005328 | G22: 0.39739661 | H22: 0.40979361 | I22: 0.41851667 | J22: 0.42446944 | K22: 0.42695733 | L22: 0.42403333 | M22: 0.41585772 | N22: 0.40179717 | O22: 0.38332472 | P22: 0.36212994 | Q22: 0.33935089 | R22: 0.31432761 | S22: 0.28678011 | T22: 0.25695175
A23: 540 | C23: =U6 -> 0.45877661 | D23: =P6 -> 0.40979361
A24: 535 | C24: =U7 -> 0.50119556 | D24: =P7 -> 0.41851667 | F24: Matriu Kt K
A25: 530 | B25: K = | C25: =U8 -> 0.52526161 | D25: =P8 -> 0.42446944 | F25: {=MMULT(F21:T22,C21:D35)} -> 3.5528614 | G25: 2.7480455
A26: 525 | C26: =U9 -> 0.53149944 | D26: =P9 -> 0.42695733 | E26: Kt K = | F26: 2.7480455 | G26: 2.1624052
A27: 520 | C27: =U10 -> 0.53050806 | D27: =P10 -> 0.42403333
A28: 515 | C28: =U11 -> 0.531857 | D28: =P11 -> 0.41585772 | F28: Matriu (Kt K)-1
A29: 510 | C29: =U12 -> 0.53505539 | D29: =P12 -> 0.40179717 | F29: {=MINVERSE(_xlfn.ANCHORARRAY(F25))} -> 16.510474 | G29: -20.981977
A30: 505 | C30: =U13 -> 0.53501539 | D30: =P13 -> 0.38332472 | E30: (Kt K)-1 = | F30: -20.981977 | G30: 27.126937
A31: 500 | C31: =U14 -> 0.52666461 | D31: =P14 -> 0.36212994
A32: 495 | C32: =U15 -> 0.50680344 | D32: =P15 -> 0.33935089 | F32: Matriu (Kt K)-1 Kt
A33: 490 | C33: =U16 -> 0.47530083 | D33: =P16 -> 0.31432761 | F33: {=MMULT(_xlfn.ANCHORARRAY(F29),_xlfn.ANCHORARRAY(F21))} -> -2.0409375 | G33: -1.7529913 | H33: -1.0236606 | I33: -0.50633067 | J33: -0.23388972 | K33: -0.18310096 | L33: -0.13811796 | M33: 0.055694232 | N33: 0.4035194 | O33: 0.79044738 | P33: 1.0972804 | Q33: 1.2473128 | R33: 1.2522275 | S33: 1.1924711 | T33: 1.1488688
A34: 485 | C34: =U17 -> 0.43667339 | D34: =P17 -> 0.28678011 | E34: (Kt K)-1 Kt = | F34: 2.7694359 | G34: 2.4115262 | H34: 1.4904051 | I34: 0.83700152 | J34: 0.49352872 | K34: 0.43013545 | L34: 0.37161759 | M34: 0.12153478 | N34: -0.32699354 | O34: -0.82725509 | P34: -1.2269887 | Q34: -1.4281881 | R34: -1.4460059 | S34: -1.3828051 | T34: -1.3411881
A35: 480 | C35: =U18 -> 0.39612578 | D35: =P18 -> 0.25695175
C37: Mostres Ni / Co (mg/L)
C38: 0,2 / 0,4 (mg/mL) | G38: 0,4 / 0,4 (mg/mL) | K38: 0,4 / 0,2 (mg/mL)
A39: Vector de les absorbàncies de la mostra-mescla | C39: Vector A | E39: Vector C | G39: Vector A | I39: Vector C | K39: Vector A | M39: Vector C
C40: ='Pràctica A'!H53 -> 0.224755 | E40: {=MMULT(F33:T34,C40:C54)} -> 0.20860382 | G40: ='Pràctica A'!I53 -> 0.297182 | I40: {=MMULT(F33:T34,G40:G54)} -> 0.46952787 | K40: ='Pràctica A'!J53 -> 0.221124 | M40: {=MMULT(F33:T34,K40:K54)} -> 0.46445305
C41: ='Pràctica A'!H54 -> 0.242007 | D41: C = | E41: 0.3964207 | G41: ='Pràctica A'!I54 -> 0.326104 | H41: C = | I41: 0.34122699 | K41: ='Pràctica A'!J54 -> 0.245724 | L41: C = | M41: 0.14175238
C42: ='Pràctica A'!H55 -> 0.257577 | G42: ='Pràctica A'!I55 -> 0.35389 | K42: ='Pràctica A'!J55 -> 0.27023
C43: ='Pràctica A'!H56 -> 0.270083 | G43: ='Pràctica A'!I56 -> 0.376455 | K43: ='Pràctica A'!J56 -> 0.290308
C44: ='Pràctica A'!H57 -> 0.277649 | G44: ='Pràctica A'!I57 -> 0.390117 | K44: ='Pràctica A'!J57 -> 0.302216
C45: ='Pràctica A'!H58 -> 0.28017 | G45: ='Pràctica A'!I58 -> 0.394721 | K45: ='Pràctica A'!J58 -> 0.306065
...

Sheet Càlculs
